Workbook

Sheet Допущения
A1: Финансовая модель: допущения
A3: Сценарий | D3: базовый | E3: ← выберите: консервативный, базовый или оптимистичный
A4: Номер сценария | D4: =IF(D3="консервативный",1,IF(D3="оптимистичный",3,2))
A6: Ключ | B6: Допущение | C6: Единица | D6: Значение / 2027 | E6: 2028 | F6: 2029 | G6: Статус | H6: Источник, как проверить
B7: Цены
A8: impl_price | B8: Внедрение (разово) | C8: ₽ | D8: 300000 | G8: оценка | H8: паспорт, п. 9: 150–500 тыс. ₽; у интеграторов RAG-ассистент — 350–800 тыс. ₽ (wehaveidea.ru)
A9: sub_dept | B9: Подписка «Отдел» (до 50 пользователей) | C9: ₽ в год | D9: 300000 | G9: оценка | H9: паспорт, п. 9
A10: sub_ent | B10: Подписка «Предприятие» (до 200 пользователей) | C10: ₽ в год | D10: 600000 | G10: оценка | H10: паспорт, п. 9
A11: ent_share | B11: Доля клиентов на «Предприятии» | C11: доля | D11: 0.3 | G11: оценка | H11: проверить на продажах
A12: module_tkp | B12: Модуль «ТКП и продажи» (реестр ТКП, бланк, почта, аналитика спроса) | C12: ₽ в год | D12: 120000 | G12: оценка | H12: паспорт: модули — от 100 тыс. ₽ в год
A13: module_tkp_share | B13: Доля клиентов с модулем «ТКП и продажи» | C13: доля | D13: 0.6 | G13: оценка
A14: module_1c | B14: Модуль «1С» (цены и остатки, учёт только на чтение) | C14: ₽ в год | D14: 100000 | G14: оценка
A15: module_1c_share | B15: Доля клиентов с модулем «1С» | C15: доля | D15: 0.3 | G15: оценка
A16: first_year_share | B16: Доля годовой подписки в год подписания | C16: доля | D16: 0.5 | G16: оценка | H16: подписание в среднем в середине года
A17: price_index | B17: Индексация цен в год | C17: доля | D17: 0.05 | G17: оценка | H17: ниже инфляции — консервативно
A18: services_price | B18: Услуги при внедрении: наполнение справочника параметров, интеграции, обучение | C18: ₽ на клиента | D18: 100000 | G18: оценка | H18: слайд «Бизнес-модель»: настройка интеграций, новые источники, обучение
A19: services_share | B19: Доля новых клиентов, покупающих услуги | C19: доля | D19: 0.6 | G19: оценка
A20: services_days | B20: Работа по услугам | C20: чел.-дн. | D20: 5 | G20: оценка | H20: справочник 3–10 дн. (trudoemkost)
B21: Клиент: затраты
A22: impl_days | B22: Внедрение, чел.-дней | C22: чел.-дн. | D22: 9 | G22: оценка | H22: docs/ekonomika/trudoemkost.md: 7–11 чел.-дн.
A23: first_factor | B23: Коэффициент для клиентов первого года (процесс не отработан) | C23: × | D23: 1.4 | G23: оценка | H23: trudoemkost.md: +30–50 %
A24: support_hours | B24: Сопровождение, ч в месяц | C24: ч | D24: 4 | G24: оценка | H24: trudoemkost.md: 2–8 ч
A25: travel | B25: Выезды на одно внедрение | C25: ₽ | D25: 20000 | G25: оценка | H25: концепция, 6.2: 10–30 тыс. ₽
A26: presale_days | B26: Предпродажа на нового клиента (показ, встречи, ТКП) | C26: чел.-дн. | D26: 5 | G26: оценка
A27: pilot_days | B27: Пилот на нового клиента | C27: чел.-дн. | D27: 10 | G27: оценка | H27: пилот 1–2 месяца, замер «до / после»
A28: channel_share | B28: Доля клиентов через интеграторов | C28: доля | D28: 0.5 | G28: оценка | H28: партнёр — интегратор, канал к его клиентам
A29: commission | B29: Комиссия интегратора с подписки | C29: доля | D29: 0.25 | G29: оценка | H29: концепция: 20–30 %
A30: churn|консервативный | B30: Отток подписок в год — консервативный | C30: доля | D30: 0.15 | G30: оценка
A31: churn|базовый | B31: Отток подписок в год — базовый | C31: доля | D31: 0.1 | G31: оценка
A32: churn|оптимистичный | B32: Отток подписок в год — оптимистичный | C32: доля | D32: 0.05 | G32: оценка
B33: Продажи
A34: new_clients|консервативный | B34: Новых клиентов в год — консервативный | C34: клиентов | D34: 1 | E34: 3 | F34: 7 | G34: оценка | H34: базовый — план паспорта, п. 24: 2 + 5 + 12
A35: new_clients|базовый | B35: Новых клиентов в год — базовый | C35: клиентов | D35: 2 | E35: 5 | F35: 12 | G35: оценка | H35: базовый — план паспорта, п. 24: 2 + 5 + 12
A36: new_clients|оптимистичный | B36: Новых клиентов в год — оптимистичный | C36: клиентов | D36: 3 | E36: 8 | F36: 18 | G36: оценка | H36: базовый — план паспорта, п. 24: 2 + 5 + 12
A37: pilots|консервативный | B37: Пилотов в год (засчитываются во внедрение) — консервативный | C37: пилотов | D37: 1 | E37: 2 | F37: 3 | G37: оценка | H37: половина пилотов переходит во внедрение
A38: pilots|базовый | B38: Пилотов в год (засчитываются во внедрение) — базовый | C38: пилотов | D38: 1 | E38: 3 | F38: 6 | G38: оценка | H38: половина пилотов переходит во внедрение
A39: pilots|оптимистичный | B39: Пилотов в год (засчитываются во внедрение) — оптимистичный | C39: пилотов | D39: 2 | E39: 4 | F39: 8 | G39: оценка | H39: половина пилотов переходит во внедрение
B40: Команда
A41: fte_dev | B41: Разработка и качество, ставок | C41: ставок | D41: 1 | E41: 1.25 | F41: 2.5 | G41: оценка
A42: fte_impl | B42: Внедрение и поддержка, ставок | C42: ставок | D42: 0.25 | E42: 0.75 | F42: 1.5 | G42: оценка | H42: в 2027 г. внедряет вся команда: разработчики помогают
...

Sheet План
A1: План на 2027–2029 — сценарий выбирается на листе «Допущения»
A2: ="Сценарий: "&'Допущения'!$D$3
A4: Показатель | D4: 2027 | E4: 2028 | F4: 2029
A5: Новых клиентов | D5: =CHOOSE('Допущения'!$D$4,'Допущения'!$D$34,'Допущения'!$D$35,'Допущения'!$D$36) | E5: =CHOOSE('Допущения'!$D$4,'Допущения'!$E$34,'Допущения'!$E$35,'Допущения'!$E$36) | F5: =CHOOSE('Допущения'!$D$4,'Допущения'!$F$34,'Допущения'!$F$35,'Допущения'!$F$36)
A6: Отток подписок | D6: =CHOOSE('Допущения'!$D$4,'Допущения'!$D$30,'Допущения'!$D$31,'Допущения'!$D$32) | E6: =CHOOSE('Допущения'!$D$4,'Допущения'!$D$30,'Допущения'!$D$31,'Допущения'!$D$32) | F6: =CHOOSE('Допущения'!$D$4,'Допущения'!$D$30,'Допущения'!$D$31,'Допущения'!$D$32)
A7: Клиентов сохранилось с прошлого года | D7: =0 | E7: =D30*(1-E6) | F7: =E30*(1-F6)
A8: Выручка с клиента в год | D8: =(('Допущения'!$D$9*(1-'Допущения'!$D$11)+'Допущения'!$D$10*'Допущения'!$D$11)+('Допущения'!$D$12*'Допущения'!$D$13+'Допущения'!$D$14*'Допущения'!$D$15))*(1+'Допущения'!$D$17)^0 | E8: =(('Допущения'!$D$9*(1-'Допущения'!$D$11)+'Допущения'!$D$10*'Допущения'!$D$11)+('Допущения'!$D$12*'Допущения'!$D$13+'Допущения'!$D$14*'Допущения'!$D$15))*(1+'Допущения'!$D$17)^1 | F8: =(('Допущения'!$D$9*(1-'Допущения'!$D$11)+'Допущения'!$D$10*'Допущения'!$D$11)+('Допущения'!$D$12*'Допущения'!$D$13+'Допущения'!$D$14*'Допущения'!$D$15))*(1+'Допущения'!$D$17)^2
A9: Выручка: подписка и модули | D9: =D7*D8+D5*D8*'Допущения'!$D$16 | E9: =E7*E8+E5*E8*'Допущения'!$D$16 | F9: =F7*F8+F5*F8*'Допущения'!$D$16
A10: Выручка: внедрение | D10: =D5*'Допущения'!$D$8*(1+'Допущения'!$D$17)^0 | E10: =E5*'Допущения'!$D$8*(1+'Допущения'!$D$17)^1 | F10: =F5*'Допущения'!$D$8*(1+'Допущения'!$D$17)^2
A11: Выручка: услуги | D11: =D5*'Допущения'!$D$19*'Допущения'!$D$18*(1+'Допущения'!$D$17)^0 | E11: =E5*'Допущения'!$D$19*'Допущения'!$D$18*(1+'Допущения'!$D$17)^1 | F11: =F5*'Допущения'!$D$19*'Допущения'!$D$18*(1+'Допущения'!$D$17)^2
A12: Выручка | D12: =D9+D10+D11 | E12: =E9+E10+E11 | F12: =F9+F10+F11
A13: Комиссия интеграторам | D13: =D9*'Допущения'!$D$28*'Допущения'!$D$29 | E13: =E9*'Допущения'!$D$28*'Допущения'!$D$29 | F13: =F9*'Допущения'!$D$28*'Допущения'!$D$29
A14: Выезды | D14: =D5*'Допущения'!$D$25 | E14: =E5*'Допущения'!$D$25 | F14: =F5*'Допущения'!$D$25
A15: Штат (масштаб) | D15: =1 | E15: =CHOOSE('Допущения'!$D$4,'Допущения'!$D$45,'Допущения'!$D$46,'Допущения'!$D$47) | F15: =CHOOSE('Допущения'!$D$4,'Допущения'!$D$45,'Допущения'!$D$46,'Допущения'!$D$47)
A16: ФОТ: разработка | D16: ='Допущения'!$D$41*D15*'Допущения'!$D$48*12*(1+'Допущения'!$D$52) | E16: ='Допущения'!$E$41*E15*'Допущения'!$E$48*12*(1+'Допущения'!$E$52) | F16: ='Допущения'!$F$41*F15*'Допущения'!$F$48*12*(1+'Допущения'!$F$52)
A17: ФОТ: внедрение и поддержка | D17: ='Допущения'!$D$42*D15*'Допущения'!$D$49*12*(1+'Допущения'!$D$52) | E17: ='Допущения'!$E$42*E15*'Допущения'!$E$49*12*(1+'Допущения'!$E$52) | F17: ='Допущения'!$F$42*F15*'Допущения'!$F$49*12*(1+'Допущения'!$F$52)
A18: ФОТ: продажи | D18: ='Допущения'!$D$43*D15*'Допущения'!$D$50*12*(1+'Допущения'!$D$52) | E18: ='Допущения'!$E$43*E15*'Допущения'!$E$50*12*(1+'Допущения'!$E$52) | F18: ='Допущения'!$F$43*F15*'Допущения'!$F$50*12*(1+'Допущения'!$F$52)
A19: ФОТ: экономика и договоры | D19: ='Допущения'!$D$44*D15*'Допущения'!$D$51*12*(1+'Допущения'!$D$52) | E19: ='Допущения'!$E$44*E15*'Допущения'!$E$51*12*(1+'Допущения'!$E$52) | F19: ='Допущения'!$F$44*F15*'Допущения'!$F$51*12*(1+'Допущения'!$F$52)
A20: Себестоимость | D20: =D13+D14+D17 | E20: =E13+E14+E17 | F20: =F13+F14+F17
A21: Валовая прибыль | D21: =D12-D20 | E21: =E12-E20 | F21: =F12-F20
A22: Прочие расходы | D22: =('Допущения'!$D$55+'Допущения'!$D$56+'Допущения'!$D$57+'Допущения'!$D$58+'Допущения'!$D$59+'Допущения'!$D$60)*(1+'Допущения'!$D$61) | E22: =('Допущения'!$E$55+'Допущения'!$E$56+'Допущения'!$E$57+'Допущения'!$E$58+'Допущения'!$E$59+'Допущения'!$E$60)*(1+'Допущения'!$D$61) | F22: =('Допущения'!$F$55+'Допущения'!$F$56+'Допущения'!$F$57+'Допущения'!$F$58+'Допущения'!$F$59+'Допущения'!$F$60)*(1+'Допущения'!$D$61)
A23: Операционные расходы | D23: =D16+D18+D19+D22 | E23: =E16+E18+E19+E22 | F23: =F16+F18+F19+F22
A24: EBITDA | D24: =D21-D23 | E24: =E21-E23 | F24: =F21-F23
A25: Страховые взносы в ФОТ | D25: =(D16+D17+D18+D19)*'Допущения'!$D$52/(1+'Допущения'!$D$52) | E25: =(E16+E17+E18+E19)*'Допущения'!$E$52/(1+'Допущения'!$E$52) | F25: =(F16+F17+F18+F19)*'Допущения'!$F$52/(1+'Допущения'!$F$52)
A26: Налог (УСН 6 % с вычетом взносов) | D26: =MAX(D12*'Допущения'!$D$63-D25,D12*'Допущения'!$D$63/2) | E26: =MAX(E12*'Допущения'!$D$63-E25,E12*'Допущения'!$D$63/2) | F26: =MAX(F12*'Допущения'!$D$63-F25,F12*'Допущения'!$D$63/2)
A27: Гранты | D27: =CHOOSE('Допущения'!$D$4,'Допущения'!$D$64,'Допущения'!$D$65,'Допущения'!$D$66) | E27: =CHOOSE('Допущения'!$D$4,'Допущения'!$E$64,'Допущения'!$E$65,'Допущения'!$E$66) | F27: =CHOOSE('Допущения'!$D$4,'Допущения'!$F$64,'Допущения'!$F$65,'Допущения'!$F$66)
A28: Денежный поток | D28: =D24-D26+D27 | E28: =E24-E26+E27 | F28: =F24-F26+F27
A29: Деньги накопленно | D29: =D28 | E29: =E28+D29 | F29: =F28+E29
A30: Активных клиентов на конец года | D30: =D7+D5 | E30: =E7+E5 | F30: =F7+F5
A31: Загрузка внедрения | D31: =(D5*'Допущения'!$D$22*'Допущения'!$D$23+D5*'Допущения'!$D$19*'Допущения'!$D$20+D30*'Допущения'!$D$24*12/8)/('Допущения'!$D$42*D15*'Допущения'!$D$53*0.8) | E31: =(E5*'Допущения'!$D$22*1+E5*'Допущения'!$D$19*'Допущения'!$D$20+E30*'Допущения'!$D$24*12/8)/('Допущения'!$E$42*E15*'Допущения'!$D$53*0.8) | F31: =(F5*'Допущения'!$D$22*1+F5*'Допущения'!$D$19*'Допущения'!$D$20+F30*'Допущения'!$D$24*12/8)/('Допущения'!$F$42*F15*'Допущения'!$D$53*0.8)

Sheet Клиент
A1: Экономика одного клиента — маржинальная, цены и ставки 2028 г.
A3: Выручка с клиента в год (2028) | B3: ='План'!E8
A4: Стоимость чел.-дня внедрения | B4: ='Допущения'!$E$49*12*(1+'Допущения'!$E$52)/'Допущения'!$D$53
A5: Выручка первого года | B5: ='Допущения'!$D$8*(1+'Допущения'!$D$17)^1+B3*'Допущения'!$D$16+'Допущения'!$D$19*'Допущения'!$D$18*(1+'Допущения'!$D$17)^1
A6: Прямые затраты первого года | B6: =('Допущения'!$D$22+'Допущения'!$D$19*'Допущения'!$D$20)*B4+'Допущения'!$D$25+'Допущения'!$D$24*12/8*B4*'Допущения'!$D$16+B3*'Допущения'!$D$16*'Допущения'!$D$28*'Допущения'!$D$29
A7: Маржа первого года | B7: =B5-B6
A8: Маржа первого года, % | B8: =B7/B5
A9: Маржа со второго года | B9: =B3*(1-'Допущения'!$D$28*'Допущения'!$D$29)-'Допущения'!$D$24*12/8*B4
A10: Маржа со второго года, % | B10: =B9/B3
A11: Стоимость привлечения (CAC) | B11: =('Допущения'!$D$26+'Допущения'!$D$27)*B4+2*'Допущения'!$D$25+'Допущения'!$E$58/MAX(CHOOSE('Допущения'!$D$4,'Допущения'!$E$34,'Допущения'!$E$35,'Допущения'!$E$36),1)
A12: Ценность клиента за 5 лет (LTV) | B12: =B7+B9*((1-CHOOSE('Допущения'!$D$4,'Допущения'!$D$30,'Допущения'!$D$31,'Допущения'!$D$32))+(1-CHOOSE('Допущения'!$D$4,'Допущения'!$D$30,'Допущения'!$D$31,'Допущения'!$D$32))^2+(1-CHOOSE('Допущения'!$D$4,'Допущения'!$D$30,'Допущения'!$D$31,'Допущения'!$D$32))^3+(1-CHOOSE('Допущения'!$D$4,'Допущения'!$D$30,'Допущения'!$D$31,'Допущения'!$D$32))^4)
A13: LTV / CAC | B13: =B12/B11
A14: Окупаемость привлечения, мес. | B14: =B11/(B9/12)

Sheet Эффект для заказчика
A1: Эффект для заказчика — ввод в оранжевых ячейках; на пилоте — замер вкладки «Эффект»
B3: Отдел техпродаж и сервиса — как в пилоте | C3: Предприятие: 80 сотрудников работают с документами — пример паспорта
A4: Сотрудников | B4: 8 | C4: 80
A5: Ответов в день на сотрудника | B5: 5 | C5: 0
A6: Минут на ответ вручную | B6: 15 | C6: 0 | D6: оценка 15 мин — заменить хронометражем у партнёра (протокол docs/pilot/zamer_i_stoimost.md)
A7: Экономия времени на ответе | B7: 0.5 | C7: 0 | D7: цель из карточки партнёра — минус 50 %; на пилоте замеряет вкладка «Эффект»
A8: ТКП в месяц | B8: 60 | C8: 60
A9: Минут на ТКП вручную | B9: 60 | C9: 60 | D9: оценка 60 мин на ТКП — заменить замером у партнёра
A10: Экономия времени на ТКП | B10: 0.5 | C10: 0.5
A11: Минут поиска в день на сотрудника | B11: 0 | C11: 40
A12: Экономия времени поиска | B12: 0 | C12: 0.3
A13: Зарплата, ₽ в месяц | B13: 80000 | C13: 80000 | D13: Рязанская область: 80 тыс. ₽ в месяц (Росстат, март 2026) — ниже, чем у инженеров (81–113 тыс. ₽)
A14: Подписка, ₽ в год | B14: 300000 | C14: 600000
A15: Модули, ₽ в год | B15: 120000 | C15: 220000
A16: Внедрение, ₽ | B16: 300000 | C16: 450000
A17: Оборудование, ₽ | B17: 200000 | C17: 200000
A18: Администратор базы знаний, ч в месяц | B18: 3 | C18: 6
A19: Час сотрудника с взносами | B19: =B13*1.3/165 | C19: =C13*1.3/165
A20: Высвобождается часов в год | B20: =(B4*B5*247*B6*B7+B8*12*B9*B10+B4*B11*B12*247)/60 | C20: =(C4*C5*247*C6*C7+C8*12*C9*C10+C4*C11*C12*247)/60
A21: Эффект, ₽ в год | B21: =B20*B19 | C21: =C20*C19
A22: Затраты первого года | B22: =B23+B16+B17 | C22: =C23+C16+C17
A23: Затраты со второго года | B23: =B14+B15+B18*12*B19+450*12 | C23: =C14+C15+C18*12*C19+450*12
A24: Окупаемость, мес. | B24: =B22/(B21/12) | C24: =C22/(C21/12)
A25: Возврат за 3 года (ROI) | B25: =(3*B21-B22-2*B23)/(B22+2*B23) | C25: =(3*C21-C22-2*C23)/(C22+2*C23)
A26: Цена — доля от эффекта | B26: =(B14+B15)/B21 | C26: =(C14+C15)/C21
A27: Запросов в год | B27: =B4*B5*247+B8*12 | C27: =C4*C5*247+C8*12
A28: Полная стоимость запроса | B28: =IF(B27>0,B23/B27,0) | C28: =IF(C27>0,C23/C27,0)
A29: Экономия на запросе | B29: =IF(B27>0,(B6*B7*B4*B5*247+B9*B10*B8*12)/B27/60*B19,0) | C29: =IF(C27>0,(C6*C7*C4*C5*247+C9*C10*C8*12)/C27/60*C19,0)

Sheet Чувствительность
A1: Деньги на конец 2029 г. (накопленно), базовый сценарий — рассчитано скриптом
A3: Допущение | B3: Хуже | C3: Базовый | D3: Лучше
A4: Новых клиентов ±30 % | B4: -3183666 | C4: 1471664.7 | D4: 6126995.4
A5: Подписка и модули ±20 % | B5: -97945.038 | C5: 1471664.7 | D5: 3041274.4
A6: Цена внедрения ±30 % | B6: -316239.3 | C6: 1471664.7 | D6: 3259568.7
A7: Оплата труда ±20 % | B7: -806835.3 | C7: 1471664.7 | D7: 3750164.7
A8: Отток 5 % / 20 % | B8: 999342.49 | C8: 1471664.7 | D8: 1714701.1
A9: Доля через интеграторов 25 % / 75 % | B9: 891187.73 | C9: 1471664.7 | D9: 2052141.7

Sheet Созданный продукт
A1: Стоимость созданного продукта — затратный подход (нормативная трудоёмкость)
A3: Работа | B3: чел.-дн.
A4: Прототип TRL 4 (03–14.10.2026): ядро, поиск, ответы с проверками, учёт, справочник, ТКП, интерфейс, поставка | B4: 167
A5: Цены из прайса, ключ к моделям, 20 писем эталона и исправления разбора | B5: 8
A6: Выбор прибора менеджером, НДС, REST API /tkp | B6: 6
A7: Папка документов отдела и безопасная запись индекса двумя процессами | B7: 7
A8: Резервная копия и перенос в новую версию | B8: 4
A9: Реестр ТКП: номер, бланк компании, Excel, статусы, напоминания, редакции | B9: 10
A10: Почта отдела → входящие запросы | B10: 6
A11: Аналитика спроса, поиск по обозначениям, цены и остатки из 1С, отчёт о пилоте | B11: 14
A12: Проверка ветки, автотесты на Windows и Python 3.11, защита установки, пакет партнёру, регистрация ПО | B12: 8
A13: Итого | B13: =SUM(B4:B12)
A15: Стоимость по ставке: ставки команды (концепция: 60 тыс. ₽ в месяц) | B15: =B13*3786.41
A16: Стоимость по ставке: рыночная ставка разработчика в Рязани (≈ 120 тыс. ₽ в месяц) | B16: =B13*7572.82
