Workbook

Sheet Трудоёмкость
A1: Сроки и трудоёмкость проекта — для расчёта себестоимости
A3: Ставка, ₽ за чел.-день с взносами | B3: 3800 | C3: 60 тыс. ₽ × 1,3 / 20,6 рабочего дня (концепция, 6.2)
A4: Часов в чел.-дне | B4: 8
A5: Ёмкость технической части, чел.-дней в неделю | B5: 5 | C5: при учёбе: 20 + 10 + 10 ч в неделю
A6: Коэффициент запаса (≈ 90 %) | B6: 1.28 | C6: ожидаемая + коэффициент × σ
A7: Сводка
A8: Этап | B8: Ожидаемо, чел.-дн. | C8: С запасом, чел.-дн. | D8: Часы | E8: Стоимость, ₽ | F8: Стоимость с запасом, ₽ | G8: Недель работы команды
A9: Этап 0. Прототип, TRL 4 — сделан | B9: =H37 | C9: =H37+$B$6*I37 | D9: =B9*$B$4 | E9: =B9*$B$3 | F9: =C9*$B$3 | G9: =B9/$B$5
A10: Этап 1. Пилотная версия и пилот у партнёра, TRL 5–6 | B10: =H50 | C10: =H50+$B$6*I50 | D10: =B10*$B$4 | E10: =B10*$B$3 | F10: =C10*$B$3 | G10: =B10/$B$5
A11: Этап 2. Коммерческая версия 1.0 — можно продавать, TRL 7 | B11: =H62 | C11: =H62+$B$6*I62 | D11: =B11*$B$4 | E11: =B11*$B$3 | F11: =C11*$B$3 | G11: =B11/$B$5
A12: Этап 3. Развитие по спросу — 2027–2028 | B12: =H73 | C12: =H73+$B$6*I73 | D12: =B12*$B$4 | E12: =B12*$B$3 | F12: =C12*$B$3 | G12: =B12/$B$5
A13: Весь путь до продаваемой версии (этапы 0–2) | B13: =H37+H50+H62 | C13: =H37+H50+H62+$B$6*(I37+I50+I62) | D13: =B13*$B$4 | E13: =B13*$B$3 | F13: =C13*$B$3 | G13: =B13/$B$5
A14: Впереди (этапы 1–2) | B14: =H50+H62 | C14: =H50+H62+$B$6*(I50+I62) | D14: =B14*$B$4 | E14: =B14*$B$3 | F14: =C14*$B$3 | G14: =B14/$B$5
A18: Этап | B18: № | C18: Работа | D18: Кто | E18: Оптимистично | F18: Вероятно | G18: Пессимистично | H18: Ожидаемо (PERT) | I18: σ | J18: Часы | K18: Стоимость, ₽ | L18: Основание
A19: Этап 0. Прототип, TRL 4 — сделан | C19: календарь — 03–14.10.2026 (история репозитория). Нормативная трудоёмкость: сколько стоит сделать уже сделанный объём при обычной производительности. Её и берут в себестоимость (затратный подход), а не число календарных дней.
A20: 0 | B20: 0.1 | C20: Исследование и архитектура: выбор моделей (GigaChat 3.1 Lightning, bge-m3, bge-reranker-v2-m3), llama.cpp, замеры скорости в режимах ПК, ноутбук 4 ГБ, без видеокарты | D20: Р | E20: 4 | F20: 6 | G20: 10 | H20: =(E20+4*F20+G20)/6 | I20: =(G20-E20)/6 | J20: =H20*$B$4 | K20: =H20*$B$3 | L20: scripts/bench_speed.py, profile_answer.py, docs/noutbuk.md
A21: 0 | B21: 0.2 | C21: Корпус для проверки: 15 открытых документов (≈ 700 стр.), 4 демо-регламента и отменённая редакция, демо-база учёта, справочник параметров (28 моделей, 114 значений с цитатами) | D21: Р, Т | E21: 6 | F21: 9 | G21: 14 | H21: =(E21+4*F21+G21)/6 | I21: =(G21-E21)/6 | J21: =H21*$B$4 | K21: =H21*$B$3 | L21: data/
A22: 0 | B22: 0.3 | C22: Разбор документов на пункты: PDF, DOCX, сканы с распознаванием, Excel, изображения; номера пунктов и страниц у каждого фрагмента | D22: Р | E22: 6 | F22: 9 | G22: 14 | H22: =(E22+4*F22+G22)/6 | I22: =(G22-E22)/6 | J22: =H22*$B$4 | K22: =H22*$B$3 | L22: kbagent/ingest.py
A23: 0 | B23: 0.4 | C23: Индекс и гибридный поиск: BM25 + векторы, переранжирование, соседние пункты; проверка на 100 тыс. фрагментов | D23: Р | E23: 3 | F23: 5 | G23: 8 | H23: =(E23+4*F23+G23)/6 | I23: =(G23-E23)/6 | J23: =H23*$B$4 | K23: =H23*$B$3 | L23: kbagent/store.py, retriever.py, scripts/bench_scale.py
A24: 0 | B24: 0.5 | C24: Ответ по фрагментам с программными проверками: ссылки, предмет, «другой случай», запреты, числа, честный отказ | D24: Р | E24: 10 | F24: 15 | G24: 25 | H24: =(E24+4*F24+G24)/6 | I24: =(G24-E24)/6 | J24: =H24*$B$4 | K24: =H24*$B$3 | L24: kbagent/answer.py; этапы 2–7 в docs/dorabotki.md
A25: 0 | B25: 0.6 | C25: Агент: диалог и уточнения, выбор источника, составные вопросы, встречный вопрос, справки, защита от подмены инструкций | D25: Р | E25: 10 | F25: 14 | G25: 22 | H25: =(E25+4*F25+G25)/6 | I25: =(G25-E25)/6 | J25: =H25*$B$4 | K25: =H25*$B$3 | L25: kbagent/agent.py
A26: 0 | B26: 0.7 | C26: Учётная база: вопрос → SQL только на чтение, слой понятных названий, записи по номеру, нечёткий поиск, «запись + правило» | D26: Р | E26: 7 | F26: 10 | G26: 15 | H26: =(E26+4*F26+G26)/6 | I26: =(G26-E26)/6 | J26: =H26*$B$4 | K26: =H26*$B$3 | L26: kbagent/database.py, demo_db.py, data/demo_db/schema.yaml
A27: 0 | B27: 0.8 | C27: Справочник параметров: подбор и проверка требований программой, сравнение моделей, расчёты по правилам, противоречия → эксперт, импорт с контролем качества | D27: Р | E27: 6 | F27: 9 | G27: 14 | H27: =(E27+4*F27+G27)/6 | I27: =(G27-E27)/6 | J27: =H27*$B$4 | K27: =H27*$B$3 | L27: kbagent/spravochnik.py, raschety.py
A28: 0 | B28: 0.9 | C28: Письмо клиента → черновик ТКП в Word, вкладка «Эффект», решения эксперта | D28: Р | E28: 6 | F28: 9 | G28: 14 | H28: =(E28+4*F28+G28)/6 | I28: =(G28-E28)/6 | J28: =H28*$B$4 | K28: =H28*$B$3 | L28: kbagent/tkp.py, effect.py, experts.py
A29: 0 | B29: 0.10 | C29: Работа с документами: редакции и «что изменилось», нормоконтроль по ГОСТ Р 7.0.97, пробелы в документации, карточки документов, ответ в Word, страница PDF с выделенным фрагментом | D29: Р | E29: 10 | F29: 14 | G29: 20 | H29: =(E29+4*F29+G29)/6 | I29: =(G29-E29)/6 | J29: =H29*$B$4 | K29: =H29*$B$3 | L29: kbagent/editions.py, normocontrol.py, gaps.py, cards.py, export.py, preview.py, uploads.py
A30: 0 | B30: 0.11 | C30: Безопасность: вход и роли, блокировка подбора пароля, журнал действий, маскирование персональных данных, ключи API | D30: Р | E30: 5 | F30: 8 | G30: 12 | H30: =(E30+4*F30+G30)/6 | I30: =(G30-E30)/6 | J30: =H30*$B$4 | K30: =H30*$B$3 | L30: kbagent/auth.py, privacy.py
A31: 0 | B31: 0.12 | C31: Интерфейс: чат и страница администрирования (журнал, оценки, документы, качество, безопасность, справочник, эксперты) | D31: Р | E31: 8 | F31: 12 | G31: 18 | H31: =(E31+4*F31+G31)/6 | I31: =(G31-E31)/6 | J31: =H31*$B$4 | K31: =H31*$B$3 | L31: app/
... A36: 0 | B36: 0.17 | C36: Документация и материалы показа: README, описание для ИТ и ИБ, сценарий показа, скриншоты, схема архитектуры | D36: Р, М | E36: 4 | F36: 6 | G36: 9 | H36: =(E36+4*F36+G36)/6 | I36: =(G36-E36)/6 | J36: =H36*$B$4 | K36: =H36*$B$3 | L36: README.md, docs/vnedrenie.md, docs/demo_script.md, docs/screens/
C37: Итого по этапу | E37: =SUM(E20:E36) | F37: =SUM(F20:F36) | G37: =SUM(G20:G36) | H37: =SUM(H20:H36) | I37: =SUM(I20:I36) | J37: =H37*$B$4 | K37: =H37*$B$3
A39: Этап 1. Пилотная версия и пилот у партнёра, TRL 5–6 | C39: ноябрь 2026 — февраль 2027. Один отдел (техпродажи или сервис), одна группа продукции — как в карточке задачи. Пилот 1–2 месяца с замером «вручную / с агентом».
A40: 1 | B40: 1.1 | C40: Документы партнёра по одной группе продукции: реестр (версия, срок действия, владелец, права), разбор на пункты, проверка распознавания сканов, словарь терминов | D40: Р, Т | E40: 3 | F40: 5 | G40: 8 | H40: =(E40+4*F40+G40)/6 | I40: =(G40-E40)/6 | J40: =H40*$B$4 | K40: =H40*$B$3 | L40: карточка задачи, п. 2
A41: 1 | B41: 1.2 | C41: Справочник параметров и прайс по группе продукции: значение, единица, документ, страница, цитата | D41: Т, Р | E41: 3 | F41: 5 | G41: 10 | H41: =(E41+4*F41+G41)/6 | I41: =(G41-E41)/6 | J41: =H41*$B$4 | K41: =H41*$B$3 | L41: число моделей неизвестно: 3–10 дней на 30–80 моделей
A42: 1 | B42: 1.3 | C42: Настройка под данные партнёра: пороги отказа и проверки предмета, роли и примеры вопросов, исправление ошибок разбора | D42: Р | E42: 3 | F42: 5 | G42: 8 | H42: =(E42+4*F42+G42)/6 | I42: =(G42-E42)/6 | J42: =H42*$B$4 | K42: =H42*$B$3 | L42: README, «Ограничения и следующие шаги»
A43: 1 | B43: 1.4 | C43: Закрытый приёмочный набор партнёра (30–50 вопросов): прогон, разбор ошибок, исправления | D43: Т, Р | E43: 3 | F43: 5 | G43: 8 | H43: =(E43+4*F43+G43)/6 | I43: =(G43-E43)/6 | J43: =H43*$B$4 | K43: =H43*$B$3 | L43: карточка задачи, п. 2 и 6
A44: 1 | B44: 1.5 | C44: Доработки к пилоту из открытых задач: цены из прайса в ТКП, ключи доступа к серверам моделей, эталон писем для ТКП до 20 | D44: Р | E44: 2 | F44: 4 | G44: 6 | H44: =(E44+4*F44+G44)/6 | I44: =(G44-E44)/6 | J44: =H44*$B$4 | K44: =H44*$B$3 | L44: Э10-10, Э7-17, Д1
A45: 1 | B45: 1.6 | C45: Установка в контуре партнёра: согласование с ИТ и ИБ, учётные записи и роли, обучение сотрудников отдела | D45: Р, М | E45: 2 | F45: 3 | G45: 5 | H45: =(E45+4*F45+G45)/6 | I45: =(G45-E45)/6 | J45: =H45*$B$4 | K45: =H45*$B$3 | L45: docs/vnedrenie.md
A46: 1 | B46: 1.7 | C46: Сопровождение пилота 1–2 месяца: ответы с 👎 и вопросы без ответа, новые редакции, исправления | D46: Р, Т | E46: 4 | F46: 7 | G46: 12 | H46: =(E46+4*F46+G46)/6 | I46: =(G46-E46)/6 | J46: =H46*$B$4 | K46: =H46*$B$3 | L46: паспорт, п. 25
A47: 1 | B47: 1.8 | C47: Замер «вручную / с агентом», отчёт об эффекте и кейс | D47: Т, М | E47: 2 | F47: 3 | G47: 5 | H47: =(E47+4*F47+G47)/6 | I47: =(G47-E47)/6 | J47: =H47*$B$4 | K47: =H47*$B$3 | L47: docs/pilot/zamer_i_stoimost.md
A48: 1 | B48: 1.9 | C48: Регистрация программы для ЭВМ в Роспатенте: реферат, депонируемые материалы, заявка | D48: М | E48: 1 | F48: 2 | G48: 3 | H48: =(E48+4*F48+G48)/6 | I48: =(G48-E48)/6 | J48: =H48*$B$4 | K48: =H48*$B$3 | L48: госпошлина 5 000 ₽ — отдельно
A49: 1 | B49: 1.10 | C49: Управление: еженедельные встречи с партнёром, планирование, отчёты | D49: М | E49: 2 | F49: 3 | G49: 5 | H49: =(E49+4*F49+G49)/6 | I49: =(G49-E49)/6 | J49: =H49*$B$4 | K49: =H49*$B$3 | L49: консультации партнёра ≈ 1 ч в неделю
...

Sheet На клиента
A1: Внедрение и сопровождение у одного клиента
A3: Работа | B3: Мин., чел.-дн. | C3: Макс., чел.-дн. | D3: Мин., ₽ | E3: Макс., ₽
A4: Подготовка документов клиента: реестр, разбор, проверка сканов | B4: 3 | C4: 5 | D4: =B4*'Трудоёмкость'!$B$3 | E4: =C4*'Трудоёмкость'!$B$3
A5: Роли и права доступа | B5: 1 | C5: 2 | D5: =B5*'Трудоёмкость'!$B$3 | E5: =C5*'Трудоёмкость'!$B$3
A6: Проверочный набор и замер качества на вопросах клиента | B6: 2 | C6: 3 | D6: =B6*'Трудоёмкость'!$B$3 | E6: =C6*'Трудоёмкость'!$B$3
A7: Обучение сотрудников | B7: 1 | C7: 1 | D7: =B7*'Трудоёмкость'!$B$3 | E7: =C7*'Трудоёмкость'!$B$3
A8: Внедрение, итого | B8: =SUM(B4:B7) | C8: =SUM(C4:C7) | D8: =SUM(D4:D7) | E8: =SUM(E4:E7)
A9: Справочник параметров — если клиенту нужен подбор и ТКП | B9: 3 | C9: 10 | D9: =B9*'Трудоёмкость'!$B$3 | E9: =C9*'Трудоёмкость'!$B$3
A11: Сопровождение | B11: Мин., ч в месяц | C11: Макс., ч в месяц | D11: Мин., ₽ в год | E11: Макс., ₽ в год
A12: Загрузка новых документов, вопросы, обновления | B12: 2 | C12: 8 | D12: =B12*12/'Трудоёмкость'!$B$4*'Трудоёмкость'!$B$3 | E12: =C12*12/'Трудоёмкость'!$B$4*'Трудоёмкость'!$B$3
A14: Для первых 2–3 клиентов закладывайте верхнюю границу и сверху 30–50 %: процесс внедрения ещё не отработан.

Sheet Учёт часов
A1: Фактические часы — с ноября 2026, чтобы после пилота заменить оценки фактом
A3: Дата | B3: Участник | C3: Этап | D3: № работы | E3: Часы | F3: Что сделано | G3: Итого часов | H3: =SUM(E4:E1000)
